<?xml version="1.0" encoding="utf-8"?>
<!-- This URDF was automatically created by SolidWorks to URDF Exporter! Originally created by Stephen Brawner (brawner@gmail.com) 
     Commit Version: 1.6.0-1-g15f4949  Build Version: 1.6.7594.29634
     For more information, please see http://wiki.ros.org/sw_urdf_exporter -->
<robot name="cr5_gripper_robot">
  <link name="dummy_link" />
  <link name="base_link">
    <inertial>
      <origin xyz="-8.0961E-06 0.0019103 0.028995" rpy="0 0 0" />
      <mass value="0.90882" />
      <inertia
        ixx="0.0014545"
        ixy="4.2968E-08"
        ixz="-1.8199E-07"
        iyy="0.001345"
        iyz="-6.243E-06"
        izz="0.002155" />
    </inertial>
    <visual>
      <origin xyz="0 0 0" rpy="0 0 0" />
      <geometry>
        <mesh filename="package://dobot_description/meshes/cr5/base_link.dae" />
      </geometry>
      <material
        name="">
        <color rgba="0 0 0 1" />
      </material>
    </visual>
    <collision>
      <origin xyz="0 0 0" rpy="0 0 0" />
      <geometry>
        <mesh filename="package://dobot_description/meshes/cr5/base_link.dae" />
      </geometry>
    </collision>
  </link>

  <joint name="dummy_joint" type="fixed">
    <parent link="dummy_link" />
    <child  link="base_link" />
  </joint>


  <link  name="Link1">
    <inertial>
      <origin xyz="-8.7268E-07 -0.0032576 -0.0076748" rpy="0 0 0" />
      <mass value="1.6123" />
      <inertia
        ixx="0.0029122"
        ixy="5.7387E-09"
        ixz="1.9945E-08"
        iyy="0.0028191"
        iyz="0.00044094"
        izz="0.0032836" />
    </inertial>
    <visual>
      <origin xyz="0 0 0" rpy="0 0 0" />
      <geometry>
        <mesh filename="package://dobot_description/meshes/cr5/Link1.dae" />
      </geometry>
      <material
        name="">
        <color rgba="1 1 1 1" />
      </material>
    </visual>
    <collision>
      <origin xyz="0 0 0" rpy="0 0 0" />
      <geometry>
        <mesh filename="package://dobot_description/meshes/cr5/Link1.dae" />
      </geometry>
    </collision>
  </link>

  <joint name="joint1" type="revolute">
    <origin xyz="0 0 0.147" rpy="0 0 0" />
    <parent link="base_link" />
    <child link="Link1" />
    <axis xyz="0 0 1" />
    <limit lower="-3.14" upper="3.14" effort="300" velocity="100" />
  </joint>

  <link name="Link2">
    <inertial>
      <origin xyz="-0.21351 -1.3842E-06 0.14252" rpy="0 0 0" />
      <mass value="5.5186" />
      <inertia
        ixx="0.0085919"
        ixy="7.5552E-07"
        ixz="-7.8922E-07"
        iyy="0.027553"
        iyz="1.4629E-07"
        izz="0.028294" />
    </inertial>
    <visual>
      <origin xyz="0 0 0" rpy="0 0 0" />
      <geometry>
        <mesh filename="package://dobot_description/meshes/cr5/Link2.dae" />
      </geometry>
      <material
        name="">
        <color rgba="1 1 1 1" />
      </material>
    </visual>
    <collision>
      <origin xyz="0 0 0" rpy="0 0 0" />
      <geometry>
        <mesh filename="package://dobot_description/meshes/cr5/Link2.dae" />
      </geometry>
    </collision>
  </link>

  <joint name="joint2" type="revolute">
    <origin xyz="0 0 0" rpy="1.5708 1.5708 0" />
    <parent link="Link1" />
    <child  link="Link2" />
    <axis xyz="0 0 1" />
    <limit lower="-3.14" upper="3.14" effort="300" velocity="100" />
  </joint>

  <link name="Link3">
    <inertial>
      <origin xyz="-0.15231 -1.4079E-07 0.022693" rpy="0 0 0" />
      <mass value="2.8536" />
      <inertia
        ixx="0.0032608"
        ixy="-3.2147E-10"
        ixz="0.00012363"
        iyy="0.0092967"
        iyz="2.9478E-10"
        izz="0.0095552" />
    </inertial>
    <visual>
      <origin xyz="0 0 0" rpy="0 0 0" />
      <geometry>
        <mesh filename="package://dobot_description/meshes/cr5/Link3.dae" />
      </geometry>
      <material
        name="">
        <color rgba="1 1 1 1" />
      </material>
    </visual>
    <collision>
      <origin xyz="0 0 0"  rpy="0 0 0" />
      <geometry>
        <mesh filename="package://dobot_description/meshes/cr5/Link3.dae" />
      </geometry>
    </collision>
  </link>

  <joint name="joint3" type="revolute">
    <origin xyz="-0.427 0 0" rpy="0 0 0" />
    <parent link="Link2" />
    <child link="Link3" />
    <axis  xyz="0 0 1" />
    <limit lower="-2.86"  upper="2.86"  effort="300" velocity="100" />
  </joint>

  <link name="Link4">
    <inertial>
      <origin xyz="-3.2386E-07 -0.002077 -0.0015548" rpy="0 0 0" />
      <mass value="0.67058" />
      <inertia
        ixx="0.00066939"
        ixy="4.1975E-10"
        ixz="-1.0734E-08"
        iyy="0.00065424"
        iyz="0.00011081"
        izz="0.00065365" />
    </inertial>
    <visual>
      <origin xyz="0 0 0" rpy="0 0 0" />
      <geometry>
        <mesh filename="package://dobot_description/meshes/cr5/Link4.dae" />
      </geometry>
      <material name="">
        <color rgba="1 1 1 1" />
      </material>
    </visual>
    <collision>
      <origin xyz="0 0 0" rpy="0 0 0" />
      <geometry>
        <mesh filename="package://dobot_description/meshes/cr5/Link4.dae" />
      </geometry>
    </collision>
  </link>

  <joint name="joint4" type="revolute">
    <origin xyz="-0.357 0 0.141" rpy="0 0 -1.5708" />
    <parent link="Link3" />
    <child link="Link4" />
    <axis xyz="0 0 1" />
    <limit lower="-3.14" upper="3.14" effort="300" velocity="100"/>
  </joint>
  <link
    name="Link5">
    <inertial>
      <origin xyz="-3.7738E-07 -0.0045777 -0.0012971" rpy="0 0 0" />
      <mass value="0.7269" />
      <inertia
        ixx="0.00073069"
        ixy="-5.7806E-09"
        ixz="6.7132E-09"
        iyy="0.00071195"
        iyz="-0.00011926"
        izz="0.00071391" />
    </inertial>
    <visual>
      <origin xyz="0 0 0" rpy="0 0 0" />
      <geometry>
        <mesh filename="package://dobot_description/meshes/cr5/Link5.dae" />
      </geometry>
      <material name="">
        <color rgba="1 1 1 1" />
      </material>
    </visual>
    <collision>
      <origin xyz="0 0 0" rpy="0 0 0" />
      <geometry>
        <mesh filename="package://dobot_description/meshes/cr5/Link5.dae" />
      </geometry>
    </collision>
  </link>

  <joint name="joint5" type="revolute">
    <origin xyz="0 -0.116 0" rpy="1.5708 0 0" />
    <parent link="Link4" />
    <child link="Link5" />
    <axis xyz="0 0 1" />
    <limit lower="-3.14" upper="3.14" effort="300" velocity="100"/>
  </joint>

  <link name="Link6">
    <inertial>
      <origin xyz="5.0777E-11 9.3774E-05 -0.019285" rpy="0 0 0" />
      <mass value="0.15789" />
      <inertia
        ixx="7.8045E-05"
        ixy="6.1582E-15"
        ixz="6.2471E-14"
        iyy="7.9168E-05"
        iyz="-1.3822E-07"
        izz="0.00012951" />
    </inertial>
    <visual>
      <origin xyz="0 0 0" rpy="0 0 0" />
      <geometry>
        <mesh filename="package://dobot_description/meshes/cr5/Link6.dae" />
      </geometry>
      <material name="">
        <color rgba="1 1 1 1" />
      </material>
    </visual>
    <collision>
      <origin xyz="0 0 0" rpy="0 0 0" />
      <geometry>
        <mesh filename="package://dobot_description/meshes/cr5/Link6.dae" />
      </geometry>
    </collision>
  </link>

  <joint name="joint6" type="revolute">
    <origin xyz="0 0.105 0"  rpy="-1.5708 0 0" />
    <parent link="Link5" />
    <child link="Link6" />
    <axis xyz="0 0 1" />
    <limit lower="-6.28" upper="6.28" effort="300" velocity="100"/>
  </joint>

  <link
    name="robotiq_85_base_link">
    <inertial>
      <origin
        xyz="0.00021987 -2.3546E-10 0.030163"
        rpy="0 0 0" />
      <mass
        value="0.30915" />
      <inertia
        ixx="0.00028972"
        ixy="-5.7879E-10"
        ixz="-1.8543E-06"
        iyy="0.00030737"
        iyz="1.682E-12"
        izz="0.00019914" />
    </inertial>
    <visual>
      <origin
        xyz="0 0 0"
        rpy="0 0 0" />
      <geometry>
        <mesh
          filename="package://robotiq_arg85_description/meshes/robotiq_85_base_link_fine.STL" />
      </geometry>
      <material
        name="">
        <color
          rgba="0.1 0.1 0.1 1" />
      </material>
    </visual>
    <collision>
      <origin
        xyz="0 0 0"
        rpy="0 0 0" />
      <geometry>
        <mesh
          filename="package://robotiq_arg85_description/meshes/robotiq_85_base_link_coarse.STL" />
      </geometry>
    </collision>
  </link>

  <joint name="gripper_joint" type="fixed">
    <origin xyz="0 0 0" rpy="0 0 0" />
    <parent link="Link6"/>
    <child link="robotiq_85_base_link"/>
    <axis xyz="0 0 1"/>
  </joint>

  
  <link
    name="left_outer_knuckle">
    <inertial>
      <origin
        xyz="0.0178331863169983 3.68915177224286E-11 0.0021442477325704"
        rpy="0 0 0" />
      <mass
        value="0.00684838849434396" />
      <inertia
        ixx="2.66832029033166E-07"
        ixy="1.66142314639824E-15"
        ixz="1.45945633322873E-07"
        iyy="1.3889233257419E-06"
        iyz="2.82951161241588E-15"
        izz="1.26603336914415E-06" />
    </inertial>
    <visual>
      <origin
        xyz="0 0 0"
        rpy="0 0 0" />
      <geometry>
        <mesh
          filename="package://robotiq_arg85_description/meshes/outer_knuckle_fine.STL" />
      </geometry>
      <material
        name="">
        <color
          rgba="0.1 0.1 0.1 1" />
      </material>
    </visual>
    <collision>
      <origin
        xyz="0 0 0"
        rpy="0 0 0" />
      <geometry>
        <mesh
          filename="package://robotiq_arg85_description/meshes/outer_knuckle_coarse.STL" />
      </geometry>
    </collision>
  </link>
  <joint
    name="finger_joint"
    type="revolute">
    <origin
      xyz="0.0306011444260539 0 0.0627920162695395"
      rpy="0 0 0" />
    <parent
      link="robotiq_85_base_link" />
    <child
      link="left_outer_knuckle" />
    <axis
      xyz="0 -1 0" />
    <limit
	  lower="0"
      upper="0.725"
      velocity="2.0"
      effort="1000" />
  </joint>
  <link
    name="left_outer_finger">
    <inertial>
      <origin
        xyz="0.00131451599174296 2.88942057994543E-15 0.0215404163180413"
        rpy="0 0 0" />
      <mass
        value="0.0273093985570947" />
      <inertia
        ixx="8.51629628283022E-06"
        ixy="2.58174336207405E-19"
        ixz="3.83829504344079E-07"
        iyy="6.9133328065108E-06"
        iyz="-7.58589926143789E-19"
        izz="2.25006832221981E-06" />
    </inertial>
    <visual>
      <origin
        xyz="0 0 0"
        rpy="0 0 0" />
      <geometry>
        <mesh
          filename="package://robotiq_arg85_description/meshes/outer_finger_fine.STL" />
      </geometry>
      <material
        name="">
        <color
          rgba="0.1 0.1 0.1 1" />
      </material>
    </visual>
    <collision>
      <origin
        xyz="0 0 0"
        rpy="0 0 0" />
      <geometry>
        <mesh
          filename="package://robotiq_arg85_description/meshes/outer_finger_coarse.STL" />
      </geometry>
    </collision>
  </link>
  <joint
    name="left_outer_finger_joint"
    type="fixed">
    <origin
      xyz="0.0316910442266543 0 -0.00193396375724605"
      rpy="0 0 0" />
    <parent
      link="left_outer_knuckle" />
    <child
      link="left_outer_finger" />
    <axis
      xyz="0 -1 0" />
  </joint>
  <link
    name="left_inner_knuckle">
    <inertial>
      <origin
        xyz="0.017097546626628 -3.93808524389535E-10 0.0224918438201868"
        rpy="0 0 0" />
      <mass
        value="0.0110930853895903" />
      <inertia
        ixx="4.23392770691541E-06"
        ixy="5.748978936968E-15"
        ixz="1.78855677119788E-06"
        iyy="3.96548790524392E-06"
        iyz="1.05464666369669E-14"
        izz="3.24068002883007E-06" />
    </inertial>
    <visual>
      <origin
        xyz="0 0 0"
        rpy="0 0 0" />
      <geometry>
        <mesh
          filename="package://robotiq_arg85_description/meshes/inner_knuckle_fine.STL" />
      </geometry>
      <material
        name="">
        <color
          rgba="0.1 0.1 0.1 1" />
      </material>
    </visual>
    <collision>
      <origin
        xyz="0 0 0"
        rpy="0 0 0" />
      <geometry>
        <mesh
          filename="package://robotiq_arg85_description/meshes/inner_knuckle_coarse.STL" />
      </geometry>
    </collision>
  </link>
  <joint
    name="left_inner_knuckle_joint"
    type="revolute">
    <origin
      xyz="0.0127000000001501 0 0.0693074999999639"
      rpy="0 0 0" />
    <parent
      link="robotiq_85_base_link" />
    <child
      link="left_inner_knuckle" />
    <axis
      xyz="0 -1 0" />
    <limit
      lower="0"
      upper="0.8757"
      velocity="2.0"
      effort="1000" />
    <mimic 
      joint="finger_joint"
      multiplier="1"
      offset="0" />
  </joint>
  <link
    name="left_inner_finger">
    <inertial>
      <origin
        xyz="0.0060275613594574 -6.29183141465421E-15 0.00669925693133241"
        rpy="0 0 0" />
      <mass
        value="0.00724255346165745" />
      <inertia
        ixx="1.47824274053603E-06"
        ixy="-3.94884463570303E-19"
        ixz="-3.45268847648622E-07"
        iyy="1.70064480838395E-06"
        iyz="3.5059838910097E-19"
        izz="4.77151336838364E-07" />
    </inertial>
    <visual>
      <origin
        xyz="0 0 0"
        rpy="0 0 0" />
      <geometry>
        <mesh
          filename="package://robotiq_arg85_description/meshes/inner_finger_fine.STL" />
      </geometry>
      <material
        name="">
        <color
          rgba="0.1 0.1 0.1 1" />
      </material>
    </visual>
    <collision>
      <origin
        xyz="0 0 0"
        rpy="0 0 0" />
      <geometry>
        <mesh
          filename="package://robotiq_arg85_description/meshes/inner_finger_coarse.STL" />
      </geometry>
    </collision>
  </link>
  <joint
    name="left_inner_finger_joint"
    type="revolute">
    <origin
      xyz="0.034585310861294 0 0.0454970193817975"
      rpy="0 0 0" />
    <parent
      link="left_inner_knuckle" />
    <child
      link="left_inner_finger" />
    <axis
      xyz="0 -1 0" />
    <limit
      lower="0"
      upper="0.8757"
      velocity="2.0"
      effort="1000" />
    <mimic 
      joint="finger_joint"
      multiplier="-1"
      offset="0" />
  </joint>
  <link
    name="right_inner_knuckle">
    <inertial>
      <origin
        xyz="0.0168606186773776 3.93808471820465E-10 0.0226699950793434"
        rpy="0 0 0" />
      <mass
        value="0.0110930853895903" />
      <inertia
        ixx="4.27134775939882E-06"
        ixy="-8.53568456728898E-15"
        ixz="1.77774229944246E-06"
        iyy="3.96548790524392E-06"
        iyz="-8.45108024914164E-15"
        izz="3.20325997634666E-06" />
    </inertial>
    <visual>
      <origin
        xyz="0 0 0"
        rpy="0 0 0" />
      <geometry>
        <mesh
          filename="package://robotiq_arg85_description/meshes/inner_knuckle_fine.STL" />
      </geometry>
      <material
        name="">
        <color
          rgba="0.1 0.1 0.1 1" />
      </material>
    </visual>
    <collision>
      <origin
        xyz="0 0 0"
        rpy="0 0 0" />
      <geometry>
        <mesh
          filename="package://robotiq_arg85_description/meshes/inner_knuckle_coarse.STL" />
      </geometry>
    </collision>
  </link>
  <joint
    name="right_inner_knuckle_joint"
    type="revolute">
    <origin
      xyz="-0.0126999999998499 0 0.0693075000000361"
      rpy="0 0 3.14159265358979" />
    <parent
      link="robotiq_85_base_link" />
    <child
      link="right_inner_knuckle" />
    <axis
      xyz="0 1 0" />
    <limit
      lower="0"
      upper="0.8757"
      velocity="2.0"
      effort="1000" />
    <mimic 
      joint="finger_joint"
      multiplier="-1"
      offset="0" />
  </joint>
  <link
    name="right_inner_finger">
    <inertial>
      <origin
        xyz="0.00602756228812038 -6.47284509480176E-15 0.00669925609578108"
        rpy="0 0 0" />
      <mass
        value="0.00724255346165744" />
      <inertia
        ixx="1.47824283625957E-06"
        ixy="-3.95952064019123E-19"
        ixz="-3.45268708875543E-07"
        iyy="1.70064480838394E-06"
        iyz="3.55286507960029E-19"
        izz="4.77151241114822E-07" />
    </inertial>
    <visual>
      <origin
        xyz="0 0 0"
        rpy="0 0 0" />
      <geometry>
        <mesh
          filename="package://robotiq_arg85_description/meshes/inner_finger_fine.STL" />
      </geometry>
      <material
        name="">
        <color
          rgba="0.1 0.1 0.1 1" />
      </material>
    </visual>
    <collision>
      <origin
        xyz="0 0 0"
        rpy="0 0 0" />
      <geometry>
        <mesh
          filename="package://robotiq_arg85_description/meshes/inner_finger_coarse.STL" />
      </geometry>
    </collision>
  </link>
  <joint
    name="right_inner_finger_joint"
    type="revolute">
    <origin
      xyz="0.0341060475457406 0 0.0458573878541688"
      rpy="0 0 0" />
    <parent
      link="right_inner_knuckle" />
    <child
      link="right_inner_finger" />
    <axis
      xyz="0 1 0" />
    <limit
      lower="0"
      upper="0.8757"
      velocity="2.0"
      effort="1000" />
    <mimic 
      joint="finger_joint"
      multiplier="1"
      offset="0" />
  </joint>
  <link
    name="right_outer_knuckle">
    <inertial>
      <origin
        xyz="0.0178097074051638 3.60493211424024E-11 0.00233123458346721"
        rpy="0 0 0" />
      <mass
        value="0.00684838849401352" />
      <inertia
        ixx="2.70004361573169E-07"
        ixy="1.59579467624491E-15"
        ixz="1.56396493788199E-07"
        iyy="1.38892332558312E-06"
        iyz="2.82357800318817E-15"
        izz="1.26286103637978E-06" />
    </inertial>
    <visual>
      <origin
        xyz="0 0 0"
        rpy="0 0 0" />
      <geometry>
        <mesh
          filename="package://robotiq_arg85_description/meshes/outer_knuckle_fine.STL" />
      </geometry>
      <material
        name="">
        <color
          rgba="0.1 0.1 0.1 1" />
      </material>
    </visual>
    <collision>
      <origin
        xyz="0 0 0"
        rpy="0 0 0" />
      <geometry>
        <mesh
          filename="package://robotiq_arg85_description/meshes/outer_knuckle_coarse.STL" />
      </geometry>
    </collision>
  </link>
  <joint
    name="right_outer_knuckle_joint"
    type="revolute">
    <origin
      xyz="-0.0306011444258893 0 0.0627920162695395"
      rpy="0 0 3.14159265358979" />
    <parent
      link="robotiq_85_base_link" />
    <child
      link="right_outer_knuckle" />
    <axis
      xyz="0 1 0" />
    <limit
      lower="0"
      upper="0.8757"
      velocity="2.0"
      effort="1000" />
    <mimic 
      joint="finger_joint"
      multiplier="-1"
      offset="0" />
  </joint>
  <link
    name="right_outer_finger">
    <inertial>
      <origin
        xyz="0.00108844269639009 -2.611488350845E-15 0.0215530225245502"
        rpy="0 0 0" />
      <mass
        value="0.0273093985570947" />
      <inertia
        ixx="8.52366028592721E-06"
        ixy="3.41683380899422E-19"
        ixz="3.18003675694284E-07"
        iyy="6.91333280651081E-06"
        iyz="7.37726682706417E-19"
        izz="2.24270431912283E-06" />
    </inertial>
    <visual>
      <origin
        xyz="0 0 0"
        rpy="0 0 0" />
      <geometry>
        <mesh
          filename="package://robotiq_arg85_description/meshes/outer_finger_fine.STL" />
      </geometry>
      <material
        name="">
        <color
          rgba="0.1 0.1 0.1 1" />
      </material>
    </visual>
    <collision>
      <origin
        xyz="0 0 0"
        rpy="0 0 0" />
      <geometry>
        <mesh
          filename="package://robotiq_arg85_description/meshes/outer_finger_coarse.STL" />
      </geometry>
    </collision>
  </link>
  <joint
    name="right_outer_finger_joint"
    type="fixed">
    <origin
      xyz="0.0317095909367246 0 -0.0016013564954687"
      rpy="0 0 0" />
    <parent
      link="right_outer_knuckle" />
    <child
      link="right_outer_finger" />
    <axis
      xyz="0 1 0" />
  </joint>

</robot>
